Workbook

Sheet Kenechukwu
A1: K Wave Media
B3: Date | C3: Close/Last | D3: Volume | E3: Open | F3: High | G3: Low | I3: Daily returns | M3: Kenechukwu
B4: 03/18/2026 | C4: 0.6857 | D4: 411346 | E4: $0.6501 | F4: $0.70 | G4: $0.6468 | I4: =LN(C4)-LN(C5) -> 0.068659587 | L4: Exp return | M4: =AVERAGE(I4:I254) -> -0.0088676091
B5: 03/17/2026 | C5: 0.6402 | D5: 162959 | E5: $0.632 | F5: $0.6599 | G5: $0.6292 | I5: =LN(C5)-LN(C6) -> 0.02916213 | L5: Variance | M5: =_xlfn.VAR.S(I4:I254) -> 0.026125959
B6: 03/16/2026 | C6: 0.6218 | D6: 191520 | E6: $0.62 | F6: $0.6441 | G6: $0.60 | I6: =LN(C6)-LN(C7) -> 0.010346035 | L6: Std. Dev | M6: =SQRT(M5) -> 0.16163526
B7: 03/13/2026 | C7: 0.6154 | D7: 140412 | E7: $0.60 | F7: $0.63 | G7: $0.60 | I7: =LN(C7)-LN(C8) -> -0.018993006
B8: 46359 | C8: 0.6272 | D8: 67202 | E8: $0.6206 | F8: $0.6371 | G8: $0.6201 | I8: =LN(C8)-LN(C9) -> 0.041506487 | M8: Ken-Morgan | N8: Ken-Lisa | O8: Morgan-Lisa
B9: 46329 | C9: 0.6017 | D9: 501583 | E9: $0.6551 | F9: $0.7665 | G9: $0.6017 | I9: =LN(C9)-LN(C10) -> -0.10527741 | L9: Covariance | M9: =_xlfn.COVARIANCE.S(Kenechukwu!I4:I254,Morgan!I4:'Morgan'!I254) -> 0.00021523673 | N9: =_xlfn.COVARIANCE.S(Kenechukwu!I4:I254,Lisa!I4:'Lisa'!I254) -> 0.00031143539 | O9: =_xlfn.COVARIANCE.S(Morgan!I4:I254,Lisa!I4:I254) -> 0.00010409411
B10: 46298 | C10: 0.6685 | D10: 90264 | E10: $0.6406 | F10: $0.7033 | G10: $0.6406 | I10: =LN(C10)-LN(C11) -> 0.021929045 | L10: Correlation | M10: =M9/(M6*Morgan!M5) -> 0.055103215 | N10: =N9/(M6*Lisa!M6) -> 0.075288013 | O10: =Morgan!O9/(Morgan!M5*Lisa!M6) -> 0.16831267
B11: 46268 | C11: 0.654 | D11: 65974 | E11: $0.62 | F11: $0.6569 | G11: $0.6175 | I11: =LN(C11)-LN(C12) -> 0.037228815
B12: 46176 | C12: 0.6301 | D12: 287516 | E12: $0.6491 | F12: $0.7199 | G12: $0.6301 | I12: =LN(C12)-LN(C13) -> 0.028003117
B13: 46145 | C13: 0.6127 | D13: 348316 | E13: $0.65 | F13: $0.7296 | G13: $0.611 | I13: =LN(C13)-LN(C14) -> -0.011844058
B14: 46115 | C14: 0.62 | D14: 44852 | E14: $0.63 | F14: $0.63 | G14: $0.61 | I14: =LN(C14)-LN(C15) -> 0.011028331
B15: 46084 | C15: 0.6132 | D15: 38357 | E15: $0.6399 | F15: $0.644 | G15: $0.6131 | I15: =LN(C15)-LN(C16) -> 0.0027761919
B16: 46056 | C16: 0.6115 | D16: 162526 | E16: $0.6438 | F16: $0.654 | G16: $0.5988 | I16: =LN(C16)-LN(C17) -> -0.059517762
B17: 02/27/2026 | C17: 0.649 | D17: 110301 | E17: $0.6268 | F17: $0.65 | G17: $0.6268 | I17: =LN(C17)-LN(C18) -> 0.0026228512
B18: 02/26/2026 | C18: 0.6473 | D18: 69008 | E18: $0.6855 | F18: $0.6856 | G18: $0.636 | I18: =LN(C18)-LN(C19) -> -0.057630349
B19: 02/25/2026 | C19: 0.6857 | D19: 133498 | E19: $0.677 | F19: $0.6895 | G19: $0.6729 | I19: =LN(C19)-LN(C20) -> 0.00072944784
B20: 02/24/2026 | C20: 0.6852 | D20: 116834 | E20: $0.7289 | F20: $0.7289 | G20: $0.6826 | I20: =LN(C20)-LN(C21) -> -0.057839248
B21: 02/23/2026 | C21: 0.726 | D21: 309455 | E21: $0.7399 | F21: $0.7533 | G21: $0.6709 | I21: =LN(C21)-LN(C22) -> -0.029050502
B22: 02/20/2026 | C22: 0.7474 | D22: 252893 | E22: $0.7717 | F22: $0.7988 | G22: $0.7445 | I22: =LN(C22)-LN(C23) -> -0.026016654
B23: 02/19/2026 | C23: 0.7671 | D23: 217604 | E23: $0.828 | F23: $0.828 | G23: $0.7623 | I23: =LN(C23)-LN(C24) -> -0.031439043
B24: 02/18/2026 | C24: 0.7916 | D24: 242701 | E24: $0.8316 | F24: $0.8857 | G24: $0.7916 | I24: =LN(C24)-LN(C25) -> -0.049295342
B25: 02/17/2026 | C25: 0.8316 | D25: 113504 | E25: $0.8466 | F25: $0.8466 | G25: $0.8106 | I25: =LN(C25)-LN(C26) -> -0.0092166551
B26: 02/13/2026 | C26: 0.8393 | D26: 161009 | E26: $0.768 | F26: $0.8424 | G26: $0.768 | I26: =LN(C26)-LN(C27) -> 0.086697312
B27: 46358 | C27: 0.7696 | D27: 129508 | E27: $0.7695 | F27: $0.7764 | G27: $0.75 | I27: =LN(C27)-LN(C28) -> 0.013869122
B28: 46328 | C28: 0.759 | D28: 63715 | E28: $0.772 | F28: $0.7838 | G28: $0.7521 | I28: =LN(C28)-LN(C29) -> 0.0092654534
B29: 46297 | C29: 0.752 | D29: 82418 | E29: $0.82 | F29: $0.825 | G29: $0.752 | I29: =LN(C29)-LN(C30) -> -0.061875404
B30: 46267 | C30: 0.8 | D30: 64595 | E30: $0.80 | F30: $0.84 | G30: $0.80 | I30: =LN(C30)-LN(C31) -> 0.038221213
B31: 46175 | C31: 0.77 | D31: 71604 | E31: $0.75 | F31: $0.8092 | G31: $0.7466 | I31: =LN(C31)-LN(C32) -> 0.025650864
B32: 46144 | C32: 0.7505 | D32: 164799 | E32: $0.8235 | F32: $0.8485 | G32: $0.7283 | I32: =LN(C32)-LN(C33) -> -0.1132573
B33: 46114 | C33: 0.8405 | D33: 125425 | E33: $0.8292 | F33: $0.8639 | G33: $0.8242 | I33: =LN(C33)-LN(C34) -> 0.0075237711
B34: 46083 | C34: 0.8342 | D34: 221840 | E34: $0.8546 | F34: $0.8699 | G34: $0.815 | I34: =LN(C34)-LN(C35) -> -0.019703902
B35: 46055 | C35: 0.8508 | D35: 188070 | E35: $0.86 | F35: $0.8632 | G35: $0.8363 | I35: =LN(C35)-LN(C36) -> -0.0049243856
B36: 01/30/2026 | C36: 0.855 | D36: 81826 | E36: $0.818 | F36: $0.8608 | G36: $0.818 | I36: =LN(C36)-LN(C37) -> 0.045462374
B37: 01/29/2026 | C37: 0.817 | D37: 169726 | E37: $0.83 | F37: $0.8452 | G37: $0.779 | I37: =LN(C37)-LN(C38) -> 0.014175892
B38: 01/28/2026 | C38: 0.8055 | D38: 108517 | E38: $0.7982 | F38: $0.8273 | G38: $0.7964 | I38: =LN(C38)-LN(C39) -> 0.025779485
B39: 01/27/2026 | C39: 0.785 | D39: 208261 | E39: $0.7737 | F39: $0.8199 | G39: $0.74 | I39: =LN(C39)-LN(C40) -> 0.11460338
B40: 01/26/2026 | C40: 0.7 | D40: 523752 | E40: $0.8105 | F40: $0.8303 | G40: $0.70 | I40: =LN(C40)-LN(C41) -> -0.22940959
B41: 01/23/2026 | C41: 0.8805 | D41: 314242 | E41: $0.81 | F41: $0.8875 | G41: $0.8022 | I41: =LN(C41)-LN(C42) -> 0.10214781
...

Sheet Morgan
A1: Meta
B3: Date | C3: Close/Last | D3: Volume | E3: Open | F3: High | G3: Low | I3: Daily Returns | L3: Avg Returns | M3: =AVERAGE(I4:I254) -> 0.00021005431
B4: 03/18/2026 | C4: 615.68 | D4: 11726300 | E4: $616.34 | F4: $622.65 | G4: $614.61 | I4: =LN(C4)-LN(C5) -> -0.011273275 | L4: Variance | M4: =_xlfn.VAR.S(I4:I254) -> 0.00058399171
B5: 03/17/2026 | C5: 622.66 | D5: 10348760 | E5: $627.985 | F5: $636.55 | G5: $621.70 | I5: =LN(C5)-LN(C6) -> -0.0076633631 | L5: Standard Deviation | M5: =SQRT(M4) -> 0.02416592
B6: 03/16/2026 | C6: 627.45 | D6: 15134850 | E6: $632.00 | F6: $634.75 | G6: $623.1004 | I6: =LN(C6)-LN(C7) -> 0.022141483
B7: 03/13/2026 | C7: 613.71 | D7: 18957640 | E7: $623.89 | F7: $629.1699 | G7: $609.55 | I7: =LN(C7)-LN(C8) -> -0.039097871
B8: 46359 | C8: 638.18 | D8: 11617490 | E8: $648.75 | F8: $653.50 | G8: $636.90 | I8: =LN(C8)-LN(C9) -> -0.025801097 | M8: Ken-Morgan | N8: Ken-Lisa | O8: Morgan-Lisa
B9: 46329 | C9: 654.86 | D9: 8977162 | E9: $654.76 | F9: $659.12 | G9: $648.36 | I9: =LN(C9)-LN(C10) -> 0.001207093 | L9: Covariance | M9: =_xlfn.COVARIANCE.S(Kenechukwu!I4:'Kenechukwu'!I254,I4:I254) -> 0.00021523673 | N9: =_xlfn.COVARIANCE.S(Kenechukwu!I4:'Kenechukwu'!I254,Lisa!I4:'Lisa'!I254) -> 0.00031143539 | O9: =_xlfn.COVARIANCE.S(Lisa!I4:'Lisa'!I254,I4:I254) -> 0.00010409411
B10: 46298 | C10: 654.07 | D10: 9859250 | E10: $653.56 | F10: $660.30 | G10: $649.00 | I10: =LN(C10)-LN(C11) -> 0.010265484 | L10: Correlation | M10: =CORREL(Kenechukwu!I4:'Kenechukwu'!I254,I4:I254) -> 0.055103215 | N10: =CORREL(Kenechukwu!I4:'Kenechukwu'!I254,Lisa!I4:'Lisa'!I254) -> 0.075288013 | O10: =CORREL(Lisa!I4:'Lisa'!I254,I4:I254) -> 0.16831267
B11: 46268 | C11: 647.39 | D11: 13489740 | E11: $634.78 | F11: $647.75 | G11: $626.78 | I11: =LN(C11)-LN(C12) -> 0.003915656
B12: 46176 | C12: 644.86 | D12: 13159360 | E12: $647.90 | F12: $649.47 | G12: $636.11 | I12: =LN(C12)-LN(C13) -> -0.02406986
B13: 46145 | C13: 660.57 | D13: 13341370 | E13: $661.93 | F13: $670.70 | G13: $650.31 | I13: =LN(C13)-LN(C14) -> -0.010780802
B14: 46115 | C14: 667.73 | D14: 10810050 | E14: $657.96 | F14: $672.77 | G14: $657.6711 | I14: =LN(C14)-LN(C15) -> 0.019126535
B15: 46084 | C15: 655.08 | D15: 12263750 | E15: $648.29 | F15: $659.04 | G15: $638.84 | I15: =LN(C15)-LN(C16) -> 0.0023230234
B16: 46056 | C16: 653.56 | D16: 9816125 | E16: $637.16 | F16: $659.94 | G16: $634.50 | I16: =LN(C16)-LN(C17) -> 0.0082659066
B17: 02/27/2026 | C17: 648.18 | D17: 15703040 | E17: $643.45 | F17: $649.44 | G17: $638.12 | I17: =LN(C17)-LN(C18) -> -0.013530804
B18: 02/26/2026 | C18: 657.01 | D18: 10637740 | E18: $650.55 | F18: $661.00 | G18: $647.50 | I18: =LN(C18)-LN(C19) -> 0.0050660061
B19: 02/25/2026 | C19: 653.69 | D19: 11330690 | E19: $642.53 | F19: $653.88 | G19: $642.14 | I19: =LN(C19)-LN(C20) -> 0.022259405
B20: 02/24/2026 | C20: 639.3 | D20: 10135650 | E20: $633.08 | F20: $641.11 | G20: $628.98 | I20: =LN(C20)-LN(C21) -> 0.0032117845
B21: 02/23/2026 | C21: 637.25 | D21: 8605909 | E21: $652.54 | F21: $657.70 | G21: $636.00 | I21: =LN(C21)-LN(C22) -> -0.028480319
B22: 02/20/2026 | C22: 655.66 | D22: 14183510 | E22: $639.685 | F22: $663.3499 | G22: $638.78 | I22: =LN(C22)-LN(C23) -> 0.016733189
B23: 02/19/2026 | C23: 644.78 | D23: 10035700 | E23: $638.57 | F23: $647.19 | G23: $636.72 | I23: =LN(C23)-LN(C24) -> 0.0024223614
B24: 02/18/2026 | C24: 643.22 | D24: 14649200 | E24: $633.80 | F24: $645.00 | G24: $628.145 | I24: =LN(C24)-LN(C25) -> 0.0061286264
B25: 02/17/2026 | C25: 639.29 | D25: 12674740 | E25: $639.495 | F25: $642.60 | G25: $628.80 | I25: =LN(C25)-LN(C26) -> -0.00075055122
B26: 02/13/2026 | C26: 639.77 | D26: 12336360 | E26: $645.10 | F26: $651.4299 | G26: $634.57 | I26: =LN(C26)-LN(C27) -> -0.015571276
B27: 46358 | C27: 649.81 | D27: 14960110 | E27: $669.97 | F27: $676.00 | G27: $645.28 | I27: =LN(C27)-LN(C28) -> -0.028640562
B28: 46328 | C28: 668.69 | D28: 14323820 | E28: $674.00 | F28: $679.2675 | G28: $657.10 | I28: =LN(C28)-LN(C29) -> -0.0030311877
B29: 46297 | C29: 670.72 | D29: 10455820 | E29: $677.60 | F29: $680.65 | G29: $669.79 | I29: =LN(C29)-LN(C30) -> -0.0096444209
B30: 46267 | C30: 677.22 | D30: 14837530 | E30: $663.18 | F30: $683.3099 | G30: $658.78 | I30: =LN(C30)-LN(C31) -> 0.02354667
B31: 46175 | C31: 661.46 | D31: 18159250 | E31: $665.49 | F31: $671.9899 | G31: $646.5001 | I31: =LN(C31)-LN(C32) -> -0.013141583
B32: 46144 | C32: 670.21 | D32: 17131790 | E32: $663.58 | F32: $681.50 | G32: $653.50 | I32: =LN(C32)-LN(C33) -> 0.0018219838
B33: 46114 | C33: 668.99 | D33: 16882760 | E33: $687.73 | F33: $688.83 | G33: $667.46 | I33: =LN(C33)-LN(C34) -> -0.033383223
B34: 46083 | C34: 691.7 | D34: 13760660 | E34: $707.37 | F34: $717.00 | G34: $686.41 | I34: =LN(C34)-LN(C35) -> -0.02104347
B35: 46055 | C35: 706.41 | D35: 14365220 | E35: $714.60 | F35: $721.30 | G35: $703.5201 | I35: =LN(C35)-LN(C36) -> -0.014182442
B36: 01/30/2026 | C36: 716.5 | D36: 23744570 | E36: $727.50 | F36: $732.17 | G36: $713.59 | I36: =LN(C36)-LN(C37) -> -0.029985543
B37: 01/29/2026 | C37: 738.31 | D37: 59852900 | E37: $737.43 | F37: $744.00 | G37: $712.55 | I37: =LN(C37)-LN(C38) -> 0.098983399
B38: 01/28/2026 | C38: 668.73 | D38: 25709600 | E38: $674.50 | F38: $677.6775 | G38: $666.10 | I38: =LN(C38)-LN(C39) -> -0.0063203609
B39: 01/27/2026 | C39: 672.97 | D39: 13297350 | E39: $674.59 | F39: $676.815 | G39: $664.66 | I39: =LN(C39)-LN(C40) -> 0.00090684076
B40: 01/26/2026 | C40: 672.36 | D40: 16327380 | E40: $665.125 | F40: $675.28 | G40: $661.2855 | I40: =LN(C40)-LN(C41) -> 0.020434631
B41: 01/23/2026 | C41: 658.76 | D41: 22797720 | E41: $644.77 | F41: $666.4899 | G41: $644.445 | I41: =LN(C41)-LN(C42) -> 0.017039734
...

Sheet Lisa
A1: L'Oreal
B3: Date | C3: Close/Last | D3: Volume | E3: Open | F3: High | G3: Low | I3: Daily returns | M3: Lisa
B4: 03/18/2026 | C4: 393.8 | D4: 6726 | E4: $406.10 | F4: $419.95 | G4: $393.80 | I4: =LN(C4)-LN(C5) -> -0.025992415 | L4: Exp return | M4: =AVERAGE(I4:I254) -> -1.3482308e-05
B5: 03/17/2026 | C5: 404.17 | D5: 500 | E5: $419.75 | F5: $420.96 | G5: $398.60 | I5: =LN(C5)-LN(C6) -> -0.014321578 | L5: Variance | M5: =_xlfn.VAR.S(I4:I254) -> 0.00065495582
B6: 03/16/2026 | C6: 410 | D6: 452 | E6: $402.262 | F6: $416.92 | G6: $399.00 | I6: =LN(C6)-LN(C7) -> 0.019540905 | L6: Std. Dev | M6: =SQRT(M5) -> 0.025592105
B7: 03/13/2026 | C7: 402.066 | D7: 369 | E7: $412.00 | F7: $425.00 | G7: $399.00 | I7: =LN(C7)-LN(C8) -> -0.066331394
B8: 46359 | C8: 429.64 | D8: 297 | E8: $428.25 | F8: $429.64 | G8: $412.1492 | I8: =LN(C8)-LN(C9) -> 0.041900028 | M8: Ken-Morgan | N8: Ken-Lisa | O8: Morgan-Lisa
B9: 46329 | C9: 412.01 | D9: 3383 | E9: $415.76 | F9: $432.88 | G9: $412.00 | I9: =LN(C9)-LN(C10) -> -0.015629269 | L9: Covariance | M9: =_xlfn.COVARIANCE.S(Kenechukwu!I4:I254,Morgan!I4:'Morgan'!I254) -> 0.00021523673 | N9: =_xlfn.COVARIANCE.S(Kenechukwu!I4:I254,Lisa!I4:'Lisa'!I254) -> 0.00031143539 | O9: =_xlfn.COVARIANCE.S(Morgan!I4:I254,Lisa!I4:I254) -> 0.00010409411
B10: 46298 | C10: 418.5 | D10: 1784 | E10: $432.50 | F10: $438.00 | G10: $418.224 | I10: =LN(C10)-LN(C11) -> -0.020224212 | L10: Correlation | M10: =M9/(Kenechukwu!M6*Morgan!M5) -> 0.055103215 | N10: =N9/(Kenechukwu!M6*Lisa!M6) -> 0.075288013 | O10: =O9/(M6*Morgan!M5) -> 0.16831267
B11: 46268 | C11: 427.05 | D11: 424 | E11: $420.7561 | F11: $439.692 | G11: $415.3919 | I11: =LN(C11)-LN(C12) -> 0.0025838293
B12: 46176 | C12: 425.948 | D12: 233 | E12: $412.55 | F12: $447.2399 | G12: $412.55 | I12: =LN(C12)-LN(C13) -> -0.04564287
B13: 46145 | C13: 445.84 | D13: 1161 | E13: $428.22 | F13: $451.30 | G13: $428.22 | I13: =LN(C13)-LN(C14) -> 0.050580524
B14: 46115 | C14: 423.85 | D14: 267 | E14: $428.732 | F14: $446.51 | G14: $423.85 | I14: =LN(C14)-LN(C15) -> -0.04390117
B15: 46084 | C15: 442.872 | D15: 268 | E15: $438.70 | F15: $448.59 | G15: $421.0191 | I15: =LN(C15)-LN(C16) -> -0.0092778054
B16: 46056 | C16: 447 | D16: 606 | E16: $457.50 | F16: $465.04 | G16: $438.79 | I16: =LN(C16)-LN(C17) -> -0.06201857
B17: 02/27/2026 | C17: 475.6 | D17: 322 | E17: $458.00 | F17: $481.72 | G17: $458.00 | I17: =LN(C17)-LN(C18) -> 0.0050590327
B18: 02/26/2026 | C18: 473.2 | D18: 231 | E18: $473.20 | F18: $473.20 | G18: $459.00 | I18: =LN(C18)-LN(C19) -> 0.025252786
B19: 02/25/2026 | C19: 461.4 | D19: 3089 | E19: $480.00 | F19: $480.00 | G19: $461.40 | I19: =LN(C19)-LN(C20) -> -0.011892591
B20: 02/24/2026 | C20: 466.92 | D20: 3928 | E20: $463.65 | F20: $479.75 | G20: $463.65 | I20: =LN(C20)-LN(C21) -> -0.0085302914
B21: 02/23/2026 | C21: 470.92 | D21: 12625 | E21: $476.576 | F21: $476.576 | G21: $458.00 | I21: =LN(C21)-LN(C22) -> -0.0081001215
B22: 02/20/2026 | C22: 474.75 | D22: 181 | E22: $478.31 | F22: $478.31 | G22: $458.32 | I22: =LN(C22)-LN(C23) -> 0.018345238
B23: 02/19/2026 | C23: 466.12 | D23: 240 | E23: $466.12 | F23: $470.00 | G23: $450.60 | I23: =LN(C23)-LN(C24) -> -0.0007077217
B24: 02/18/2026 | C24: 466.45 | D24: 491 | E24: $474.45 | F24: $474.45 | G24: $452.25 | I24: =LN(C24)-LN(C25) -> 0.018543692
B25: 02/17/2026 | C25: 457.88 | D25: 1076 | E25: $457.00 | F25: $479.99 | G25: $456.77 | I25: =LN(C25)-LN(C26) -> 0.022707165
B26: 02/13/2026 | C26: 447.6 | D26: 10626 | E26: $442.70 | F26: $455.00 | G26: $433.65 | I26: =LN(C26)-LN(C27) -> 0.063645265
B27: 46358 | C27: 420 | D27: 520 | E27: $472.20 | F27: $472.20 | G27: $420.00 | I27: =LN(C27)-LN(C28) -> -0.1235021
B28: 46328 | C28: 475.21 | D28: 24865 | E28: $475.21 | F28: $475.21 | G28: $456.55 | I28: =LN(C28)-LN(C29) -> 0.00037885166
B29: 46297 | C29: 475.03 | D29: 24808 | E29: $485.40 | F29: $485.40 | G29: $460.12 | I29: =LN(C29)-LN(C30) -> 0.02479188
B30: 46267 | C30: 463.3979 | D30: 174 | E30: $464.151 | F30: $464.151 | G30: $453.00 | I30: =LN(C30)-LN(C31) -> -0.022621241
B31: 46175 | C31: 474 | D31: 275 | E31: $474.00 | F31: $476.10 | G31: $450.01 | I31: =LN(C31)-LN(C32) -> 0
B32: 46144 | C32: 474 | D32: 215 | E32: $472.50 | F32: $475.25 | G32: $450.01 | I32: =LN(C32)-LN(C33) -> 0.012311767
B33: 46114 | C33: 468.2 | D33: 857 | E33: $468.70 | F33: $480.88 | G33: $467.7614 | I33: =LN(C33)-LN(C34) -> 0.044995579
B34: 46083 | C34: 447.6 | D34: 300 | E34: $465.222 | F34: $465.222 | G34: $444.80 | I34: =LN(C34)-LN(C35) -> -0.038545948
B35: 46055 | C35: 465.19 | D35: 296 | E35: $472.40 | F35: $472.40 | G35: $450.76 | I35: =LN(C35)-LN(C36) -> -0.00036537532
B36: 01/30/2026 | C36: 465.36 | D36: 477 | E36: $467.28 | F36: $467.28 | G36: $446.80 | I36: =LN(C36)-LN(C37) -> -0.0046177813
B37: 01/29/2026 | C37: 467.5139 | D37: 394 | E37: $485.61 | F37: $485.61 | G37: $442.91 | I37: =LN(C37)-LN(C38) -> 0.042635848
B38: 01/28/2026 | C38: 448 | D38: 470 | E38: $472.40 | F38: $472.40 | G38: $448.00 | I38: =LN(C38)-LN(C39) -> 0.0016978691
B39: 01/27/2026 | C39: 447.24 | D39: 4193 | E39: $447.32 | F39: $466.13 | G39: $441.05 | I39: =LN(C39)-LN(C40) -> -0.040660994
B40: 01/26/2026 | C40: 465.8 | D40: 334 | E40: $466.12 | F40: $466.12 | G40: $441.00 | I40: =LN(C40)-LN(C41) -> 0.0010310165
B41: 01/23/2026 | C41: 465.32 | D41: 564 | E41: $460.00 | F41: $471.23 | G41: $437.00 | I41: =LN(C41)-LN(C42) -> -0.0027470186
...

Sheet Portfolio
AR1: St Dev | AS1: Exp Ret
B2: w1 | C2: w2 | D2: w3 | F2: Port Var | G2: Port StDev | H2: Port Exp Ret | K2: Matrix portfolio of expected returns | AR2: {=_xlfn.TOCOL(L41:AP71)} -> 0.060995219 | AS2: {=_xlfn.TOCOL(L5:AP35)} -> 0.0025756947
B3: 0 | C3: 0 | D3: =1-B3-C3 -> 1 | F3: =(B3^2*$D$6) + (C3^2*$D$7) + (D3^2*$D$8) + 2*B3*C3*$F$6 + 2*B3*D3*$F$7 + 2*C3*D3*$F$8 -> 0.00065495582 | G3: =SQRT(F3) -> 0.025592105 | H3: =B3*$B$6 + C3*$B$7 + D3*$B$8 -> -1.3482308e-05 | AR3: 0.058290536 | AS3: 0.0023986122
K4: =$H$3 -> -1.3482308e-05 | L4: -0.3 | M4: -0.28 | N4: -0.26 | O4: -0.24 | P4: -0.22 | Q4: -0.2 | R4: -0.18 | S4: -0.16 | T4: -0.14 | U4: -0.12 | V4: -0.1 | W4: -0.08 | X4: -0.06 | Y4: -0.04 | Z4: -0.02 | AA4: -9.9920072e-16 | AB4: 0.02 | AC4: 0.04 | AD4: 0.06 | AE4: 0.08 | AF4: 0.1 | AG4: 0.12 | AH4: 0.14 | AI4: 0.16 | AJ4: 0.18 | AK4: 0.2 | AL4: 0.22 | AM4: 0.24 | AN4: 0.26 | AO4: 0.28 | AP4: 0.3 | AR4: 0.055642457 | AS4: 0.0022215297
K5: -0.3 | L5: 0.0025756947 | M5: 0.0023986122 | N5: 0.0022215297 | O5: 0.0020444471 | P5: 0.0018673646 | Q5: 0.0016902821 | R5: 0.0015131995 | S5: 0.001336117 | T5: 0.0011590345 | U5: 0.00098195192 | V5: 0.00080486938 | W5: 0.00062778685 | X5: 0.00045070431 | Y5: 0.00027362178 | Z5: 9.6539243e-05 | AA5: -8.0543293e-05 | AB5: -0.00025762583 | AC5: -0.00043470836 | AD5: -0.0006117909 | AE5: -0.00078887343 | AF5: -0.00096595597 | AG5: -0.0011430385 | AH5: -0.001320121 | AI5: -0.0014972036 | AJ5: -0.0016742861 | AK5: -0.0018513686 | AL5: -0.0020284512 | AM5: -0.0022055337 | AN5: -0.0023826163 | AO5: -0.0025596988 | AP5: -0.0027367813 | AR5: 0.053059455 | AS5: 0.0020444471
A6: Mean K | B6: =AVERAGE(Kenechukwu!I4:'Kenechukwu'!I254) -> -0.0088676091 | C6: Var K | D6: =_xlfn.VAR.S(Kenechukwu!I4:I254) -> 0.026125959 | E6: Cov(K,Meta) | F6: =_xlfn.COVARIANCE.S(Kenechukwu!I4:I254,Morgan!I4:'Morgan'!I254) -> 0.00021523673 | K6: -0.28 | L6: 0.0025801655 | M6: 0.0024030829 | N6: 0.0022260004 | O6: 0.0020489179 | P6: 0.0018718353 | Q6: 0.0016947528 | R6: 0.0015176703 | S6: 0.0013405877 | T6: 0.0011635052 | U6: 0.00098642265 | V6: 0.00080934012 | W6: 0.00063225758 | X6: 0.00045517505 | Y6: 0.00027809251 | Z6: 0.00010100998 | AA6: -7.607256e-05 | AB6: -0.0002531551 | AC6: -0.00043023763 | AD6: -0.00060732017 | AE6: -0.0007844027 | AF6: -0.00096148524 | AG6: -0.0011385678 | AH6: -0.0013156503 | AI6: -0.0014927328 | AJ6: -0.0016698154 | AK6: -0.0018468979 | AL6: -0.0020239804 | AM6: -0.002201063 | AN6: -0.0023781455 | AO6: -0.0025552281 | AP6: -0.0027323106 | AR6: 0.050551509 | AS6: 0.0018673646
A7: Mean Meta | B7: =AVERAGE(Morgan!I4:I254) -> 0.00021005431 | C7: Var Meta | D7: =_xlfn.VAR.S(Morgan!I4:I254) -> 0.00058399171 | E7: Cov(K,L'Oreal) | F7: =_xlfn.COVARIANCE.S(Kenechukwu!I4:I254,Lisa!I4:'Lisa'!I254) -> 0.00031143539 | K7: -0.26 | L7: 0.0025846362 | M7: 0.0024075537 | N7: 0.0022304711 | O7: 0.0020533886 | P7: 0.0018763061 | Q7: 0.0016992235 | R7: 0.001522141 | S7: 0.0013450585 | T7: 0.0011679759 | U7: 0.00099089338 | V7: 0.00081381085 | W7: 0.00063672831 | X7: 0.00045964578 | Y7: 0.00028256324 | Z7: 0.00010548071 | AA7: -7.1601828e-05 | AB7: -0.00024868436 | AC7: -0.0004257669 | AD7: -0.00060284943 | AE7: -0.00077993197 | AF7: -0.0009570145 | AG7: -0.001134097 | AH7: -0.0013111796 | AI7: -0.0014882621 | AJ7: -0.0016653446 | AK7: -0.0018424272 | AL7: -0.0020195097 | AM7: -0.0021965923 | AN7: -0.0023736748 | AO7: -0.0025507573 | AP7: -0.0027278399 | AR7: 0.048130351 | AS7: 0.0016902821
A8: Mean L'Oreal | B8: =AVERAGE(Lisa!I4:'Lisa'!I254) -> -1.3482308e-05 | C8: Var L'Oreal | D8: =_xlfn.VAR.S(Lisa!I4:I254) -> 0.00065495582 | E8: Cov(Meta, L'Oreal) | F8: =_xlfn.COVARIANCE.S(Morgan!I4:I254,Lisa!I4:I254) -> 0.00010409411 | K8: -0.24 | L8: 0.0025891069 | M8: 0.0024120244 | N8: 0.0022349419 | O8: 0.0020578593 | P8: 0.0018807768 | Q8: 0.0017036943 | R8: 0.0015266117 | S8: 0.0013495292 | T8: 0.0011724467 | U8: 0.00099536412 | V8: 0.00081828158 | W8: 0.00064119905 | X8: 0.00046411651 | Y8: 0.00028703397 | Z8: 0.00010995144 | AA8: -6.7131096e-05 | AB8: -0.00024421363 | AC8: -0.00042129617 | AD8: -0.0005983787 | AE8: -0.00077546124 | AF8: -0.00095254377 | AG8: -0.0011296263 | AH8: -0.0013067088 | AI8: -0.0014837914 | AJ8: -0.0016608739 | AK8: -0.0018379564 | AL8: -0.002015039 | AM8: -0.0021921215 | AN8: -0.0023692041 | AO8: -0.0025462866 | AP8: -0.0027233691 | AR8: 0.045809745 | AS8: 0.0015131995
K9: -0.22 | L9: 0.0025935777 | M9: 0.0024164951 | N9: 0.0022394126 | O9: 0.0020623301 | P9: 0.0018852475 | Q9: 0.001708165 | R9: 0.0015310825 | S9: 0.0013539999 | T9: 0.0011769174 | U9: 0.00099983485 | V9: 0.00082275231 | W9: 0.00064566978 | X9: 0.00046858724 | Y9: 0.00029150471 | Z9: 0.00011442217 | AA9: -6.2660363e-05 | AB9: -0.0002397429 | AC9: -0.00041682543 | AD9: -0.00059390797 | AE9: -0.0007709905 | AF9: -0.00094807304 | AG9: -0.0011251556 | AH9: -0.0013022381 | AI9: -0.0014793206 | AJ9: -0.0016564032 | AK9: -0.0018334857 | AL9: -0.0020105683 | AM9: -0.0021876508 | AN9: -0.0023647333 | AO9: -0.0025418159 | AP9: -0.0027188984 | AR9: 0.043605748 | AS9: 0.001336117
K10: -0.2 | L10: 0.0025980484 | M10: 0.0024209659 | N10: 0.0022438833 | O10: 0.0020668008 | P10: 0.0018897183 | Q10: 0.0017126357 | R10: 0.0015355532 | S10: 0.0013584707 | T10: 0.0011813881 | U10: 0.0010043056 | V10: 0.00082722305 | W10: 0.00065014051 | X10: 0.00047305797 | Y10: 0.00029597544 | Z10: 0.0001188929 | AA10: -5.8189631e-05 | AB10: -0.00023527217 | AC10: -0.0004123547 | AD10: -0.00058943724 | AE10: -0.00076651977 | AF10: -0.00094360231 | AG10: -0.0011206848 | AH10: -0.0012977674 | AI10: -0.0014748499 | AJ10: -0.0016519324 | AK10: -0.001829015 | AL10: -0.0020060975 | AM10: -0.0021831801 | AN10: -0.0023602626 | AO10: -0.0025373451 | AP10: -0.0027144277 | AR10: 0.041536926 | AS10: 0.0011590345
K11: -0.18 | L11: 0.0026025191 | M11: 0.0024254366 | N11: 0.0022483541 | O11: 0.0020712715 | P11: 0.001894189 | Q11: 0.0017171065 | R11: 0.0015400239 | S11: 0.0013629414 | T11: 0.0011858588 | U11: 0.0010087763 | V11: 0.00083169378 | W11: 0.00065461124 | X11: 0.00047752871 | Y11: 0.00030044617 | Z11: 0.00012336364 | AA11: -5.3718899e-05 | AB11: -0.00023080143 | AC11: -0.00040788397 | AD11: -0.0005849665 | AE11: -0.00076204904 | AF11: -0.00093913158 | AG11: -0.0011162141 | AH11: -0.0012932966 | AI11: -0.0014703792 | AJ11: -0.0016474617 | AK11: -0.0018245443 | AL11: -0.0020016268 | AM11: -0.0021787093 | AN11: -0.0023557919 | AO11: -0.0025328744 | AP11: -0.0027099569 | AR11: 0.039624458 | AS11: 0.00098195192
K12: -0.16 | L12: 0.0026069899 | M12: 0.0024299073 | N12: 0.0022528248 | O12: 0.0020757423 | P12: 0.0018986597 | Q12: 0.0017215772 | R12: 0.0015444947 | S12: 0.0013674121 | T12: 0.0011903296 | U12: 0.001013247 | V12: 0.00083616451 | W12: 0.00065908197 | X12: 0.00048199944 | Y12: 0.0003049169 | Z12: 0.00012783437 | AA12: -4.9248167e-05 | AB12: -0.0002263307 | AC12: -0.00040341324 | AD12: -0.00058049577 | AE12: -0.00075757831 | AF12: -0.00093466084 | AG12: -0.0011117434 | AH12: -0.0012888259 | AI12: -0.0014659084 | AJ12: -0.001642991 | AK12: -0.0018200735 | AL12: -0.0019971561 | AM12: -0.0021742386 | AN12: -0.0023513211 | AO12: -0.0025284037 | AP12: -0.0027054862 | AR12: 0.037892024 | AS12: 0.00080486938
K13: -0.14 | L13: 0.0026114606 | M13: 0.0024343781 | N13: 0.0022572955 | O13: 0.002080213 | P13: 0.0019031305 | Q13: 0.0017260479 | R13: 0.0015489654 | S13: 0.0013718828 | T13: 0.0011948003 | U13: 0.0010177178 | V13: 0.00084063524 | W13: 0.00066355271 | X13: 0.00048647017 | Y13: 0.00030938764 | Z13: 0.0001323051 | AA13: -4.4777434e-05 | AB13: -0.00022185997 | AC13: -0.0003989425 | AD13: -0.00057602504 | AE13: -0.00075310758 | AF13: -0.00093019011 | AG13: -0.0011072726 | AH13: -0.0012843552 | AI13: -0.0014614377 | AJ13: -0.0016385203 | AK13: -0.0018156028 | AL13: -0.0019926853 | AM13: -0.0021697679 | AN13: -0.0023468504 | AO13: -0.0025239329 | AP13: -0.0027010155 | AR13: 0.036365365 | AS13: 0.00062778685
K14: -0.12 | L14: 0.0026159313 | M14: 0.0024388488 | N14: 0.0022617663 | O14: 0.0020846837 | P14: 0.0019076012 | Q14: 0.0017305187 | R14: 0.0015534361 | S14: 0.0013763536 | T14: 0.001199271 | U14: 0.0010221885 | V14: 0.00084510597 | W14: 0.00066802344 | X14: 0.0004909409 | Y14: 0.00031385837 | Z14: 0.00013677583 | AA14: -4.0306702e-05 | AB14: -0.00021738924 | AC14: -0.00039447177 | AD14: -0.00057155431 | AE14: -0.00074863684 | AF14: -0.00092571938 | AG14: -0.0011028019 | AH14: -0.0012798844 | AI14: -0.001456967 | AJ14: -0.0016340495 | AK14: -0.0018111321 | AL14: -0.0019882146 | AM14: -0.0021652971 | AN14: -0.0023423797 | AO14: -0.0025194622 | AP14: -0.0026965447 | AR14: 0.035071362 | AS14: 0.00045070431
K15: -0.1 | L15: 0.0026204021 | M15: 0.0024433195 | N15: 0.002266237 | O15: 0.0020891545 | P15: 0.0019120719 | Q15: 0.0017349894 | R15: 0.0015579068 | S15: 0.0013808243 | T15: 0.0012037418 | U15: 0.0010266592 | V15: 0.00084957671 | W15: 0.00067249417 | X15: 0.00049541164 | Y15: 0.0003183291 | Z15: 0.00014124657 | AA15: -3.583597e-05 | AB15: -0.00021291851 | AC15: -0.00039000104 | AD15: -0.00056708358 | AE15: -0.00074416611 | AF15: -0.00092124865 | AG15: -0.0010983312 | AH15: -0.0012754137 | AI15: -0.0014524963 | AJ15: -0.0016295788 | AK15: -0.0018066613 | AL15: -0.0019837439 | AM15: -0.0021608264 | AN15: -0.0023379089 | AO15: -0.0025149915 | AP15: -0.002692074 | AR15: 0.034036563 | AS15: 0.00027362178
K16: -0.08 | L16: 0.0026248728 | M16: 0.0024477903 | N16: 0.0022707077 | O16: 0.0020936252 | P16: 0.0019165427 | Q16: 0.0017394601 | R16: 0.0015623776 | S16: 0.001385295 | T16: 0.0012082125 | U16: 0.00103113 | V16: 0.00085404744 | W16: 0.0006769649 | X16: 0.00049988237 | Y16: 0.00032279983 | Z16: 0.0001457173 | AA16: -3.1365237e-05 | AB16: -0.00020844777 | AC16: -0.00038553031 | AD16: -0.00056261284 | AE16: -0.00073969538 | AF16: -0.00091677791 | AG16: -0.0010938604 | AH16: -0.001270943 | AI16: -0.0014480255 | AJ16: -0.0016251081 | AK16: -0.0018021906 | AL16: -0.0019792731 | AM16: -0.0021563557 | AN16: -0.0023334382 | AO16: -0.0025105207 | AP16: -0.0026876033 | AR16: 0.03328515 | AS16: 9.6539243e-05
K17: -0.06 | L17: 0.0026293435 | M17: 0.002452261 | N17: 0.0022751785 | O17: 0.0020980959 | P17: 0.0019210134 | Q17: 0.0017439308 | R17: 0.0015668483 | S17: 0.0013897658 | T17: 0.0012126832 | U17: 0.0010356007 | V17: 0.00085851817 | W17: 0.00068143564 | X17: 0.0005043531 | Y17: 0.00032727057 | Z17: 0.00015018803 | AA17: -2.6894505e-05 | AB17: -0.00020397704 | AC17: -0.00038105958 | AD17: -0.00055814211 | AE17: -0.00073522465 | AF17: -0.00091230718 | AG17: -0.0010893897 | AH17: -0.0012664723 | AI17: -0.0014435548 | AJ17: -0.0016206373 | AK17: -0.0017977199 | AL17: -0.0019748024 | AM17: -0.0021518849 | AN17: -0.0023289675 | AO17: -0.00250605 | AP17: -0.0026831325 | AR17: 0.032836583 | AS17: -8.0543293e-05
K18: -0.04 | L18: 0.0026338143 | M18: 0.0024567317 | N18: 0.0022796492 | O18: 0.0021025667 | P18: 0.0019254841 | Q18: 0.0017484016 | R18: 0.001571319 | S18: 0.0013942365 | T18: 0.001217154 | U18: 0.0010400714 | V18: 0.0008629889 | W18: 0.00068590637 | X18: 0.00050882383 | Y18: 0.0003317413 | Z18: 0.00015465876 | AA18: -2.2423773e-05 | AB18: -0.00019950631 | AC18: -0.00037658884 | AD18: -0.00055367138 | AE18: -0.00073075391 | AF18: -0.00090783645 | AG18: -0.001084919 | AH18: -0.0012620015 | AI18: -0.0014390841 | AJ18: -0.0016161666 | AK18: -0.0017932491 | AL18: -0.0019703317 | AM18: -0.0021474142 | AN18: -0.0023244967 | AO18: -0.0025015793 | AP18: -0.0026786618 | AR18: 0.032703327 | AS18: -0.00025762583
K19: -0.02 | L19: 0.002638285 | M19: 0.0024612025 | N19: 0.0022841199 | O19: 0.0021070374 | P19: 0.0019299548 | Q19: 0.0017528723 | R19: 0.0015757898 | S19: 0.0013987072 | T19: 0.0012216247 | U19: 0.0010445422 | V19: 0.00086745964 | W19: 0.0006903771 | X19: 0.00051329457 | Y19: 0.00033621203 | Z19: 0.00015912949 | AA19: -1.7953041e-05 | AB19: -0.00019503558 | AC19: -0.00037211811 | AD19: -0.00054920065 | AE19: -0.00072628318 | AF19: -0.00090336572 | AG19: -0.0010804483 | AH19: -0.0012575308 | AI19: -0.0014346133 | AJ19: -0.0016116959 | AK19: -0.0017887784 | AL19: -0.0019658609 | AM19: -0.0021429435 | AN19: -0.002320026 | AO19: -0.0024971085 | AP19: -0.0026741911 | AR19: 0.032889216 | AS19: -0.00043470836
K20: -9.9920072e-16 | L20: 0.0026427557 | M20: 0.0024656732 | N20: 0.0022885907 | O20: 0.0021115081 | P20: 0.0019344256 | Q20: 0.001757343 | R20: 0.0015802605 | S20: 0.001403178 | T20: 0.0012260954 | U20: 0.0010490129 | V20: 0.00087193037 | W20: 0.00069484783 | X20: 0.0005177653 | Y20: 0.00034068276 | Z20: 0.00016360023 | AA20: -1.3482308e-05 | AB20: -0.00019056484 | AC20: -0.00036764738 | AD20: -0.00054472991 | AE20: -0.00072181245 | AF20: -0.00089889498 | AG20: -0.0010759775 | AH20: -0.0012530601 | AI20: -0.0014301426 | AJ20: -0.0016072251 | AK20: -0.0017843077 | AL20: -0.0019613902 | AM20: -0.0021384727 | AN20: -0.0023155553 | AO20: -0.0024926378 | AP20: -0.0026697203 | AR20: 0.033388918 | AS20: -0.0006117909
... K35: 0.3 | L35: 0.0027098167 | M35: 0.0025327342 | N35: 0.0023556516 | O35: 0.0021785691 | P35: 0.0020014866 | Q35: 0.001824404 | R35: 0.0016473215 | S35: 0.001470239 | T35: 0.0012931564 | U35: 0.0011160739 | V35: 0.00093899135 | W35: 0.00076190882 | X35: 0.00058482628 | Y35: 0.00040774375 | Z35: 0.00023066121 | AA35: 5.3578676e-05 | AB35: -0.00012350386 | AC35: -0.00030058639 | AD35: -0.00047766893 | AE35: -0.00065475147 | AF35: -0.000831834 | AG35: -0.0010089165 | AH35: -0.0011859991 | AI35: -0.0013630816 | AJ35: -0.0015401641 | AK35: -0.0017172467 | AL35: -0.0018943292 | AM35: -0.0020714117 | AN35: -0.0022484943 | AO35: -0.0024255768 | AP35: -0.0026026594 | AR35: 0.055293428 | AS35: 0.0022260004
AR36: 0.052696772 | AS36: 0.0020489179
AR37: 0.050174323 | AS37: 0.0018718353
K38: Matrix Portfolio of Standard Deviations | AR38: 0.047737848 | AS38: 0.0016947528
AR39: 0.045401188 | AS39: 0.0015176703
K40: =$G$3 -> 0.025592105 | L40: -0.3 | M40: -0.28 | N40: -0.26 | O40: -0.24 | P40: -0.22 | Q40: -0.2 | R40: -0.18 | S40: -0.16 | T40: -0.14 | U40: -0.12 | V40: -0.1 | W40: -0.08 | X40: -0.06 | Y40: -0.04 | Z40: -0.02 | AA40: -9.9920072e-16 | AB40: 0.02 | AC40: 0.04 | AD40: 0.06 | AE40: 0.08 | AF40: 0.1 | AG40: 0.12 | AH40: 0.14 | AI40: 0.16 | AJ40: 0.18 | AK40: 0.2 | AL40: 0.22 | AM40: 0.24 | AN40: 0.26 | AO40: 0.28 | AP40: 0.3 | AR40: 0.043180553 | AS40: 0.0013405877
K41: -0.3 | L41: 0.060995219 | M41: 0.058290536 | N41: 0.055642457 | O41: 0.053059455 | P41: 0.050551509 | Q41: 0.048130351 | R41: 0.045809745 | S41: 0.043605748 | T41: 0.041536926 | U41: 0.039624458 | V41: 0.037892024 | W41: 0.036365365 | X41: 0.035071362 | Y41: 0.034036563 | Z41: 0.03328515 | AA41: 0.032836583 | AB41: 0.032703327 | AC41: 0.032889216 | AD41: 0.033388918 | AE41: 0.034188676 | AF41: 0.035268084 | AG41: 0.036602409 | AH41: 0.038164924 | AI41: 0.039928848 | AJ41: 0.041868733 | AK41: 0.043961292 | AL41: 0.046185777 | AM41: 0.048524048 | AN41: 0.050960444 | AO41: 0.053481557 | AP41: 0.056075962 | AR41: 0.041094755 | AS41: 0.0011635052
K42: -0.28 | L42: 0.060670994 | M42: 0.057954319 | N42: 0.055293428 | O42: 0.052696772 | P42: 0.050174323 | Q42: 0.047737848 | R42: 0.045401188 | S42: 0.043180553 | T42: 0.041094755 | U42: 0.039165342 | V42: 0.037416515 | W42: 0.035874693 | X42: 0.034567586 | Y42: 0.033522662 | Z42: 0.032765014 | AA42: 0.032314856 | AB42: 0.032185091 | AC42: 0.032379572 | AD42: 0.032892548 | AE42: 0.033709483 | AF42: 0.034808981 | AG42: 0.03616528 | AH42: 0.037750712 | AI42: 0.039537722 | AJ42: 0.041500279 | AK42: 0.04361469 | AL42: 0.045859958 | AM42: 0.048217805 | AN42: 0.050672518 | AO42: 0.053210694 | AP42: 0.055820948 | AR42: 0.039165342 | AS42: 0.00098642265
K43: -0.26 | L43: 0.060351859 | M43: 0.057623296 | N43: 0.054949687 | O43: 0.052339453 | P43: 0.04980256 | Q43: 0.047350798 | R43: 0.044998085 | S43: 0.042760772 | T43: 0.040657915 | U43: 0.038711432 | V43: 0.036946045 | W43: 0.035388868 | X43: 0.034068463 | Y43: 0.033013251 | Z43: 0.032249276 | AA43: 0.031797535 | AB43: 0.031671393 | AC43: 0.031874715 | AD43: 0.0324013 | AE43: 0.033235786 | AF43: 0.034355743 | AG43: 0.035734342 | AH43: 0.037342947 | AI43: 0.03915322 | AJ43: 0.041138547 | AK43: 0.043274841 | AL43: 0.045540862 | AM43: 0.047918209 | AN43: 0.050391129 | AO43: 0.052946232 | AP43: 0.055572183 | AR43: 0.037416515 | AS43: 0.00080934012
K44: -0.24 | L44: 0.060037895 | M44: 0.057297556 | N44: 0.054611331 | O44: 0.051987609 | P44: 0.049436342 | Q44: 0.046969338 | R44: 0.044600583 | S44: 0.042346567 | T44: 0.040226582 | U44: 0.038262913 | V44: 0.03648081 | W44: 0.034908093 | X44: 0.0335742 | Y44: 0.032508541 | Z44: 0.031738147 | AA44: 0.031284839 | AB44: 0.031162458 | AC44: 0.031374877 | AD44: 0.03191541 | AE44: 0.032767825 | AF44: 0.033908608 | AG44: 0.035309822 | AH44: 0.036941843 | AI44: 0.038775539 | AJ44: 0.040783717 | AK44: 0.042941904 | AL44: 0.045228631 | AM44: 0.047625387 | AN44: 0.050116388 | AO44: 0.052688269 | AP44: 0.055329751 | AR44: 0.035874693 | AS44: 0.00063225758
A45: Portfolio Efficient/Inefficient | B45: St Dev (X-axis) | C45: Exp Return (Y-axis) | K45: -0.22 | L45: 0.059729184 | M45: 0.056977191 | N45: 0.054278463 | O45: 0.051641352 | P45: 0.049075793 | Q45: 0.046593605 | R45: 0.044208834 | S45: 0.041938103 | T45: 0.039800934 | U45: 0.037819977 | V45: 0.036021014 | W45: 0.034432581 | X45: 0.033085015 | Y45: 0.032008753 | Z45: 0.031231855 | AA45: 0.030777 | AB45: 0.030658524 | AC45: 0.030880299 | AD45: 0.031435126 | AE45: 0.032305848 | AF45: 0.033467819 | AG45: 0.034891954 | AH45: 0.036547618 | AI45: 0.03840488 | AJ45: 0.04043597 | AK45: 0.042616041 | AL45: 0.044923409 | AM45: 0.047339464 | AN45: 0.049848404 | AO45: 0.052436899 | AP45: 0.055093737 | AR45: 0.034567586 | AS45: 0.00045517505
A46: Across | B46: 0.03 | C46: -0.00058 | K46: -0.2 | L46: 0.059425808 | M46: 0.056662291 | N46: 0.053951184 | O46: 0.051300796 | P46: 0.048721038 | Q46: 0.046223737 | R46: 0.043822992 | S46: 0.041535548 | T46: 0.039381155 | U46: 0.037382823 | V46: 0.035566866 | W46: 0.033962551 | X46: 0.032601138 | Y46: 0.031514124 | Z46: 0.03073064 | AA46: 0.030274261 | AB46: 0.03015984 | AC46: 0.030391241 | AD46: 0.030960708 | AE46: 0.031850116 | AF46: 0.03303363 | AG46: 0.03448098 | AH46: 0.036160499 | AI46: 0.038041449 | AJ46: 0.040095491 | AK46: 0.042297416 | AL46: 0.044625339 | AM46: 0.047060564 | AN46: 0.049587287 | AO46: 0.05219222 | AP46: 0.054864223 | AR46: 0.033522662 | AS46: 0.00027809251
A47: Bcross | B47: 0.04 | C47: -0.001899 | K47: -0.18 | L47: 0.059127848 | M47: 0.056352948 | N47: 0.053629595 | O47: 0.050966054 | P47: 0.048372205 | Q47: 0.045859877 | R47: 0.043443213 | S47: 0.041139077 | T47: 0.038967436 | U47: 0.036951655 | V47: 0.035118585 | W47: 0.033498234 | X47: 0.032122808 | Y47: 0.031024898 | Z47: 0.030234752 | AA47: 0.029776881 | AB47: 0.029666673 | AC47: 0.029907971 | AD47: 0.030492432 | AE47: 0.031400901 | AF47: 0.032606305 | AG47: 0.03407715 | AH47: 0.035780715 | AI47: 0.037685454 | AJ47: 0.039762466 | AK47: 0.041986194 | AL47: 0.044334565 | AM47: 0.046788816 | AN47: 0.049333146 | AO47: 0.051954324 | AP47: 0.054641291 | AR47: 0.032765014 | AS47: 0.00010100998
A48: Ccross | B48: 0.05 | C48: -0.002488 | K48: -0.16 | L48: 0.058835388 | M48: 0.056049254 | N48: 0.053313801 | O48: 0.050637242 | P48: 0.048029424 | Q48: 0.045502169 | R48: 0.04306966 | S48: 0.040748868 | T48: 0.03855997 | U48: 0.036526686 | V48: 0.0346764 | W48: 0.033039872 | X48: 0.031650276 | Y48: 0.030541336 | Z48: 0.02974446 | AA48: 0.029285133 | AB48: 0.0291793 | AC48: 0.029430776 | AD48: 0.030030584 | AE48: 0.030958486 | AF48: 0.032186117 | AG48: 0.03368072 | AH48: 0.035408502 | AI48: 0.037337108 | AJ48: 0.039437085 | AK48: 0.04168254 | AL48: 0.044051232 | AM48: 0.046524342 | AN48: 0.049086089 | AO48: 0.051723306 | AP48: 0.054425022 | AR48: 0.032314856 | AS48: -7.607256e-05
A49: Acircle | B49: 0.03 | C49: 0.00069 | K49: -0.14 | L49: 0.058548509 | M49: 0.055751302 | N49: 0.053003904 | O49: 0.050314476 | P49: 0.047692825 | Q49: 0.045150759 | R49: 0.042702494 | S49: 0.040365101 | T49: 0.038158959 | U49: 0.036108135 | V49: 0.034240547 | W49: 0.032587715 | X49: 0.031183806 | Y49: 0.030063711 | Z49: 0.029260043 | AA49: 0.028799305 | AB49: 0.028698019 | AC49: 0.028959955 | AD49: 0.029575465 | AE49: 0.030523167 | AF49: 0.03177335 | AG49: 0.033291954 | AH49: 0.035044103 | AI49: 0.036996628 | AJ49: 0.039119538 | AK49: 0.041386621 | AL49: 0.043775485 | AM49: 0.046267268 | AN49: 0.048846224 | AO49: 0.051499258 | AP49: 0.054215496 | AR49: 0.032185091 | AS49: -0.0002531551
A50: Bcircle | B50: 0.04 | C50: 0.001376 | K50: -0.12 | L50: 0.058267294 | M50: 0.055459183 | N50: 0.052700009 | O50: 0.049997873 | P50: 0.047362539 | Q50: 0.044805796 | R50: 0.042341882 | S50: 0.039987962 | T50: 0.037764608 | U50: 0.035696227 | V50: 0.03381127 | W50: 0.032142026 | X50: 0.030723674 | Y50: 0.02959231 | Z50: 0.0287818 | AA50: 0.028319703 | AB50: 0.028223139 | AC50: 0.028495825 | AD50: 0.029127391 | AE50: 0.030095253 | AF50: 0.031368296 | AG50: 0.032911126 | AH50: 0.034687762 | AI50: 0.036664232 | AJ50: 0.038810016 | AK50: 0.041098605 | AL50: 0.043507467 | AM50: 0.046017719 | AN50: 0.048613658 | AO50: 0.051282272 | AP50: 0.05401279 | AR50: 0.032379572 | AS50: -0.00043023763
A51: Ccircle | B51: 0.05 | C51: 0.002085 | K51: -0.1 | L51: 0.057991825 | M51: 0.055172991 | N51: 0.05240222 | O51: 0.049687551 | P51: 0.047038699 | Q51: 0.044467429 | R51: 0.041987993 | S51: 0.03961764 | T51: 0.037377128 | U51: 0.035291194 | V51: 0.033388824 | W51: 0.031703077 | X51: 0.030270169 | Y51: 0.029127437 | Z51: 0.028310041 | AA51: 0.027846647 | AB51: 0.027754991 | AC51: 0.028038718 | AD51: 0.028686692 | AE51: 0.029675063 | AF51: 0.030971258 | AG51: 0.032538512 | AH51: 0.034339731 | AI51: 0.036340142 | AJ51: 0.038508715 | AK51: 0.040818658 | AL51: 0.043247322 | AM51: 0.045775817 | AN51: 0.048388495 | AO51: 0.051072437 | AP51: 0.053816983 | AR51: 0.032892548 | AS51: -0.00060732017
K52: -0.08 | L52: 0.057722184 | M52: 0.054892819 | N52: 0.052110641 | O52: 0.049383628 | P52: 0.04672144 | Q52: 0.04413581 | R52: 0.041640999 | S52: 0.03925433 | T52: 0.036996735 | U52: 0.034893278 | V52: 0.032973469 | W52: 0.031271153 | X52: 0.029823593 | Y52: 0.028669407 | Z52: 0.027845099 | AA52: 0.027380478 | AB52: 0.027293919 | AC52: 0.027588982 | AD52: 0.028253713 | AE52: 0.02926293 | AF52: 0.030582549 | AG52: 0.032174399 | AH52: 0.034000265 | AI52: 0.036024583 | AJ52: 0.038215828 | AK52: 0.040546947 | AL52: 0.042995194 | AM52: 0.045541684 | AN52: 0.048170839 | AO52: 0.050869842 | AP52: 0.053628149 | AR52: 0.033709483 | AS52: -0.0007844027
K53: -0.06 | L53: 0.057458455 | M53: 0.054618758 | N53: 0.051825378 | O53: 0.049086224 | P53: 0.046410897 | Q53: 0.043811092 | R53: 0.041301073 | S53: 0.038898225 | T53: 0.036623649 | U53: 0.034502722 | V53: 0.032565479 | W53: 0.030846547 | X53: 0.029384264 | Y53: 0.028218555 | Z53: 0.027387318 | AA53: 0.026921552 | AB53: 0.02684029 | AC53: 0.027146985 | AD53: 0.027828814 | AE53: 0.0288592 | AF53: 0.030202489 | AG53: 0.031819078 | AH53: 0.033669624 | AI53: 0.03571778 | AJ53: 0.03793155 | AK53: 0.04028364 | AL53: 0.042751224 | AM53: 0.045315441 | AN53: 0.047960792 | AO53: 0.050674574 | AP53: 0.053446363 | AR53: 0.034808981 | AS53: -0.00096148524
K54: -0.04 | L54: 0.057200717 | M54: 0.054350901 | N54: 0.051546536 | O54: 0.048795457 | P54: 0.046107205 | Q54: 0.043493431 | R54: 0.040968391 | S54: 0.038549528 | T54: 0.036258097 | U54: 0.034119781 | V54: 0.032165133 | W54: 0.030429567 | X54: 0.028952509 | Y54: 0.02777523 | Z54: 0.026937065 | AA54: 0.026470247 | AB54: 0.026394486 | AC54: 0.026713111 | AD54: 0.027412371 | AE54: 0.028464229 | AF54: 0.02983141 | AG54: 0.031472848 | AH54: 0.033348069 | AI54: 0.035419961 | AJ54: 0.037656076 | AK54: 0.040028901 | AL54: 0.042515553 | AM54: 0.045097206 | AN54: 0.047758456 | AO54: 0.050486718 | AP54: 0.053271697 | AR54: 0.03616528 | AS54: -0.0011385678
...
